{"errorMessage":"An error occurred (500) when calling the DescribeLogGroups operation (reached max retries: 4): <!DOCTYPE HTML PUBLIC \"-//W3C//DTD HTML 3.2 Final//EN\">\n<title>500 Internal Server Error</title>\n<h1>Internal Server Error</h1>\n<p>The server encountered an internal error and was unable to complete your request. Either the server is overloaded or there is an error in the application.</p>\n","errorType":"ClientError","stackTrace":["  File \"/opt/code/localstack/localstack/services/awslambda/lambda_api.py\", line 795, in run_lambda\n    result = LAMBDA_EXECUTOR.execute(\n","  File \"/opt/code/localstack/localstack/services/awslambda/lambda_executors.py\", line 458, in execute\n    return do_execute()\n","  File \"/opt/code/localstack/localstack/services/awslambda/lambda_executors.py\", line 448, in do_execute\n    return _run(func_arn=func_arn)\n","  File \"/opt/code/localstack/localstack/utils/cloudwatch/cloudwatch_util.py\", line 158, in wrapped\n    raise e\n","  File \"/opt/code/localstack/localstack/utils/cloudwatch/cloudwatch_util.py\", line 154, in wrapped\n    result = func(*args, **kwargs)\n","  File \"/opt/code/localstack/localstack/services/awslambda/lambda_executors.py\", line 435, in _run\n    raise e\n","  File \"/opt/code/localstack/localstack/services/awslambda/lambda_executors.py\", line 431, in _run\n    result = self._execute(lambda_function, inv_context)\n","  File \"/opt/code/localstack/localstack/services/awslambda/lambda_executors.py\", line 747, in _execute\n    result = self.run_lambda_executor(lambda_function=lambda_function, inv_context=inv_context)\n","  File \"/opt/code/localstack/localstack/services/awslambda/lambda_executors.py\", line 666, in run_lambda_executor\n    store_lambda_logs(lambda_function, log_output)\n","  File \"/opt/code/localstack/localstack/services/awslambda/lambda_utils.py\", line 153, in store_lambda_logs\n    return store_cloudwatch_logs(log_group_name, log_stream_name, log_output, invocation_time)\n","  File \"/opt/code/localstack/localstack/utils/cloudwatch/cloudwatch_util.py\", line 71, in store_cloudwatch_logs\n    log_groups = logs_client.describe_log_groups()[\"logGroups\"]\n","  File \"/opt/code/localstack/.venv/lib/python3.8/site-packages/botocore/client.py\", line 391, in _api_call\n    return self._make_api_call(operation_name, kwargs)\n","  File \"/opt/code/localstack/.venv/lib/python3.8/site-packages/botocore/client.py\", line 719, in _make_api_call\n    raise error_class(parsed_response, operation_name)\n"]}
